<?xml version="1.0" ?>
<!-- =================================================================================== -->
<!-- |    This document was autogenerated by xacro from floating_canadarm_camera.urdf.xacro | -->
<!-- |    EDITING THIS FILE BY HAND IS NOT RECOMMENDED                                 | -->
<!-- =================================================================================== -->
<!-- URDF Created from information in the following Paper:

Nguyen, Phung Khac, and Peter C. Hughes. "Teleoperation: from the space shuttle to the space station." Progress in astronautics and aeronautics 161 (1994): 353-353.

The link CoM locations (with respect to link frame) are set to zero as the inertia tensor is defined with respect to the link frame in the paper.

 -->
<robot name="floating canadarm">
  <gazebo>
    <plugin filename="libign_ros2_control-system" name="ign_ros2_control::IgnitionROS2ControlPlugin">
      <robot_param>robot_description</robot_param>
      <robot_param_node>robot_state_publisher</robot_param_node>
      <parameters>/home/spaceros-user/demos_ws/install/canadarm/share/canadarm/config/floating_canadarm_control.yaml</parameters>
    </plugin>
    <plugin filename="ignition-gazebo-pose-publisher-system" name="ignition::gazebo::systems::PosePublisher">
      <publish_model_pose>true</publish_model_pose>
      <publish_nested_model_pose>true</publish_nested_model_pose>
      <use_pose_vector_msg>false</use_pose_vector_msg>
      <update_frequency>10</update_frequency>
    </plugin>
    <plugin filename="ignition-gazebo-sensors-system" name="ignition::gazebo::systems::Sensors">
      <render_engine>ogre2</render_engine>
    </plugin>
  </gazebo>
  <gazebo reference="camera_link">
    <sensor name="camera_sensor" type="camera">
      <visualize>1</visualize>
      <update_rate>10.0</update_rate>
      <camera>
        <pose>1.0 0 0 0 0 -1.57</pose>
        <horizontal_fov>1.3962634</horizontal_fov>
        <image>
          <width>800</width>
          <height>800</height>
          <format>R8G8B8</format>
        </image>
        <clip>
          <near>0.01</near>
          <far>100</far>
        </clip>
        <noise>
          <type>gaussian</type>
          <stddev>0.007</stddev>
        </noise>
      </camera>
      <always_on>1</always_on>
      <topic>/SSRMS_camera/ee/image_raw</topic>
    </sensor>
  </gazebo>
  <gazebo reference="base_camera_link">
    <sensor name="camera_sensor" type="camera">
      <visualize>1</visualize>
      <update_rate>10.0</update_rate>
      <camera>
        <pose>1.0 0 0 0 0 -1.57</pose>
        <!-- <horizontal_fov>1.3962634</horizontal_fov> -->
        <horizontal_fov>1.7</horizontal_fov>
        <image>
          <width>800</width>
          <height>800</height>
          <format>R8G8B8</format>
        </image>
        <clip>
          <near>0.01</near>
          <far>100</far>
        </clip>
        <noise>
          <type>gaussian</type>
          <stddev>0.007</stddev>
        </noise>
      </camera>
      <always_on>1</always_on>
      <topic>/SSRMS_camera/base/image_raw</topic>
    </sensor>
  </gazebo>
  <!-- Colors -->
  <material name="white">
    <color rgba="1 1 1 1"/>
  </material>
  <material name="blue">
    <color rgba="0 0 1 1"/>
  </material>
  <material name="red">
    <color rgba="1 0 0 1"/>
  </material>
  <material name="green">
    <color rgba="0 1 0 1"/>
  </material>
  <link name="world"/>
  <joint name="world_to_vx" type="fixed">
    <parent link="world"/>
    <child link="v_x_link"/>
    <origin rpy="0 0 0" xyz="0 0 0"/>
  </joint>
  <link name="v_x_link">
    <inertial>
      <mass value="0.00001"/>
      <origin rpy="0 0 0" xyz="0 0 0"/>
      <inertia ixx="1e-9" ixy="0" ixz="0" iyy="1e-9" iyz="0" izz="1e-9"/>
    </inertial>
  </link>
  <joint name="v_x_joint" type="prismatic">
    <parent link="v_x_link"/>
    <child link="v_y_link"/>
    <origin rpy="0 0 0" xyz="0 0 0"/>
    <axis xyz="1 0 0"/>
    <limit effort="1000.0" lower="-10000.0" upper="10000.0" velocity="5.0"/>
  </joint>
  <link name="v_y_link">
    <inertial>
      <mass value="0.00001"/>
      <origin rpy="0 0 0" xyz="0 0 0"/>
      <inertia ixx="1e-9" ixy="0" ixz="0" iyy="1e-9" iyz="0" izz="1e-9"/>
    </inertial>
  </link>
  <joint name="v_y_joint" type="prismatic">
    <parent link="v_y_link"/>
    <child link="v_z_link"/>
    <origin rpy="0 0 0" xyz="0 0 0"/>
    <axis xyz="0 1 0"/>
    <limit effort="1000.0" lower="-10000.0" upper="10000.0" velocity="5.0"/>
  </joint>
  <link name="v_z_link">
    <inertial>
      <mass value="0.00001"/>
      <origin rpy="0 0 0" xyz="0 0 0"/>
      <inertia ixx="1e-9" ixy="0" ixz="0" iyy="1e-9" iyz="0" izz="1e-9"/>
    </inertial>
  </link>
  <joint name="v_z_joint" type="prismatic">
    <parent link="v_z_link"/>
    <child link="v_r_link"/>
    <origin rpy="0 0 0" xyz="0.0 0 -0.0"/>
    <axis xyz="0 0 1"/>
    <limit effort="1000.0" lower="-10000.0" upper="10000.0" velocity="5.0"/>
  </joint>
  <link name="v_r_link">
    <inertial>
      <mass value="0.00001"/>
      <origin rpy="0 0 0" xyz="0 0 0"/>
      <inertia ixx="1e-9" ixy="0" ixz="0" iyy="1e-9" iyz="0" izz="1e-9"/>
    </inertial>
  </link>
  <joint name="v_r_joint" type="revolute">
    <parent link="v_r_link"/>
    <child link="v_p_link"/>
    <origin rpy="0 0 0" xyz="0.0 0 -0.0"/>
    <axis xyz="1 0 0"/>
    <limit effort="1000.0" lower="-6.28" upper="6.28" velocity="5.0"/>
  </joint>
  <link name="v_p_link">
    <inertial>
      <mass value="0.00001"/>
      <origin rpy="0 0 0" xyz="0 0 0"/>
      <inertia ixx="1e-9" ixy="0" ixz="0" iyy="1e-9" iyz="0" izz="1e-9"/>
    </inertial>
  </link>
  <joint name="v_p_joint" type="revolute">
    <parent link="v_p_link"/>
    <child link="v_yaw_link"/>
    <origin rpy="0 0 0" xyz="0.0 0 -0.0"/>
    <axis xyz="0 1 0"/>
    <limit effort="1000.0" lower="-6.28" upper="6.28" velocity="5.0"/>
  </joint>
  <link name="v_yaw_link">
    <inertial>
      <mass value="0.00001"/>
      <origin rpy="0 0 0" xyz="0 0 0"/>
      <inertia ixx="1e-9" ixy="0" ixz="0" iyy="1e-9" iyz="0" izz="1e-9"/>
    </inertial>
  </link>
  <joint name="v_yaw_joint" type="revolute">
    <parent link="v_yaw_link"/>
    <child link="ISS"/>
    <origin rpy="0 0 0" xyz="0.0 0 -0.0"/>
    <axis xyz="0 0 1"/>
    <limit effort="1000.0" lower="-6.28" upper="6.28" velocity="5.0"/>
  </joint>
  <link name="ISS">
    <inertial>
      <origin rpy="0 0 0" xyz="0 0 0"/>
      <mass value="1000.0"/>
      <inertia ixx="1" ixy="0" ixz="0" iyy="1" iyz="0" izz="1"/>
    </inertial>
    <visual>
      <origin rpy="0 0 0" xyz="0 0 0"/>
      <geometry>
        <mesh filename="package://simulation/models/canadarm/meshes/iss.dae" scale="1.0 1.0 1.0"/>
      </geometry>
    </visual>
    <collision>
      <origin rpy="0 0 0" xyz="0 0 0"/>
      <geometry>
        <mesh filename="package://simulation/models/canadarm/meshes/iss.stl" scale="1.0 1.0 1.0"/>
      </geometry>
    </collision>
  </link>
  <joint name="ISS_joint" type="fixed">
    <parent link="ISS"/>
    <child link="Base_SSRMS"/>
    <origin rpy="3.1416 0 0" xyz="0 0 3.6"/>
  </joint>
  <!-- SSRMS_Canadarm2 Dummy Base Body-->
  <link name="Base_SSRMS">
    <inertial>
      <origin rpy="0 0 0" xyz="0 0 0.5"/>
      <mass value="243.66"/>
      <inertia ixx="44.413" ixy="0" ixz="0" iyy="44.413" iyz="0" izz="9.336"/>
    </inertial>
    <visual>
      <origin rpy="0 0 0" xyz="0 0 0"/>
      <geometry>
        <mesh filename="package://simulation/models/canadarm/meshes/ee.dae" scale="1.0 1.0 1.0"/>
      </geometry>
    </visual>
    <collision>
      <origin rpy="0 0 0" xyz="0 0 0"/>
      <geometry>
        <mesh filename="package://simulation/models/canadarm/meshes/ee.stl" scale="1.0 1.0 1.0"/>
      </geometry>
    </collision>
  </link>
  <!-- Dummy Joint Joining Base to Body B1 -->
  <joint name="Base_Joint" type="revolute">
    <parent link="Base_SSRMS"/>
    <child link="B1"/>
    <!-- Rotate Frame to Match the frames on Fig. 13 in Paper -->
    <origin rpy="0 0 0" xyz="0 0 0"/>
    <axis xyz="0 0 1"/>
    <limit effort="2332" lower="-4.71239" upper="4.71239" velocity="0.0698132"/>
  </joint>
  <!--Manipulator-->
  <!-- Link 1 -->
  <link name="B1">
    <inertial>
      <origin rpy="0 -1.5708 0" xyz="0.25082 0 -0.175"/>
      <mass value="105.98"/>
      <inertia ixx="12.19" ixy="0" ixz="0" iyy="12.19" iyz="0" izz="3.061"/>
    </inertial>
    <visual>
      <origin rpy="0 -1.5708 0" xyz="0.25082 0 -0.175"/>
      <geometry>
        <mesh filename="package://simulation/models/canadarm/meshes/joint_v3_0.dae" scale="1.0 1.0 1.0"/>
      </geometry>
    </visual>
    <collision>
      <origin rpy="0 -1.5708 0" xyz="0.25082 0 -0.175"/>
      <geometry>
        <mesh filename="package://simulation/models/canadarm/meshes/joint_v3_0.stl" scale="1.0 1.0 1.0"/>
      </geometry>
    </collision>
  </link>
  <!-- Joint 1: Shoulder Roll Joint -->
  <joint name="Shoulder_Roll" type="revolute">
    <parent link="B1"/>
    <child link="B2"/>
    <origin rpy="0 0 0" xyz="0.25082 0 -0.175"/>
    <axis xyz="1 0 0"/>
    <limit effort="2332" lower="-4.71239" upper="4.71239" velocity="0.0698132"/>
  </joint>
  <!-- Link 2 -->
  <link name="B2">
    <inertial>
      <origin rpy="0 0 0" xyz="0.175 0 -0.25082"/>
      <mass value="105.98"/>
      <inertia ixx="12.19" ixy="0" ixz="0" iyy="12.13" iyz="0" izz="3.061"/>
    </inertial>
    <visual>
      <origin rpy="0 0 0" xyz="0.175 0 -0.25082"/>
      <geometry>
        <mesh filename="package://simulation/models/canadarm/meshes/joint_v3_0.dae" scale="1.0 1.0 1.0"/>
      </geometry>
    </visual>
    <collision>
      <origin rpy="0 0 0" xyz="0.175 0 -0.25082"/>
      <geometry>
        <mesh filename="package://simulation/models/canadarm/meshes/joint_v3_0.stl" scale="1.0 1.0 1.0"/>
      </geometry>
    </collision>
  </link>
  <!-- Joint 2: Shoulder Yaw Joint -->
  <joint name="Shoulder_Yaw" type="revolute">
    <parent link="B2"/>
    <child link="B3"/>
    <origin rpy="0 0 0" xyz="0.175 0 -0.25082"/>
    <axis xyz="0 0 1"/>
    <limit effort="2332" lower="-4.71239" upper="4.71239" velocity="0.0698132"/>
  </joint>
  <!-- Link 3 -->
  <link name="B3">
    <inertial>
      <origin rpy="3.14 0 0" xyz="4.0 0 -0.175"/>
      <mass value="314.88"/>
      <inertia ixx="15.41" ixy="0" ixz="0" iyy="2094.71" iyz="0" izz="2103.19"/>
    </inertial>
    <visual>
      <origin rpy="0 -1.5708 0" xyz="0.25082 0 -0.175"/>
      <geometry>
        <mesh filename="package://simulation/models/canadarm/meshes/joint_v3_0.dae" scale="1.0 1.0 1.0"/>
      </geometry>
    </visual>
    <collision>
      <origin rpy="0 -1.5708 0" xyz="0.25082 0 -0.175"/>
      <geometry>
        <mesh filename="package://simulation/models/canadarm/meshes/joint_v3_0.stl" scale="1.0 1.0 1.0"/>
      </geometry>
    </collision>
    <visual>
      <origin rpy="-1.5708 0 -1.5708" xyz="0.25082 0 -0.175"/>
      <geometry>
        <mesh filename="package://simulation/models/canadarm/meshes/long_link_1_v3_0.dae" scale="1.0 1.0 1.0"/>
      </geometry>
    </visual>
    <collision>
      <origin rpy="-1.5708 0 -1.5708" xyz="0.25082 0 -0.175"/>
      <geometry>
        <mesh filename="package://simulation/models/canadarm/meshes/long_link_1_v3_0.stl" scale="1.0 1.0 1.0"/>
      </geometry>
    </collision>
    <visual>
      <origin rpy="0 1.5708 0" xyz="7.36082 0 -0.175"/>
      <geometry>
        <mesh filename="package://simulation/models/canadarm/meshes/joint_v3_0.dae" scale="1.0 1.0 1.0"/>
      </geometry>
    </visual>
    <collision>
      <origin rpy="0 1.5708 0" xyz="7.36082 0 -0.175"/>
      <geometry>
        <mesh filename="package://simulation/models/canadarm/meshes/joint_v3_0.stl" scale="1.0 1.0 1.0"/>
      </geometry>
    </collision>
    <visual>
      <origin rpy="0 0 1.5708" xyz="7.61164 0 -0.35"/>
      <geometry>
        <cylinder length="0.5" radius="0.165"/>
      </geometry>
    </visual>
  </link>
  <!-- Joint 4: Elbow Pitch Joint -->
  <joint name="Elbow_Pitch" type="revolute">
    <parent link="B3"/>
    <child link="B4"/>
    <origin rpy="0 0 0" xyz="7.61164 0 -0.6"/>
    <axis xyz="0 0 1"/>
    <limit effort="2332" lower="-4.71239" upper="4.71239" velocity="0.0698132"/>
  </joint>
  <!-- Link 5 -->
  <link name="B4">
    <inertial>
      <origin rpy="0 0 0" xyz="-3.6 0 -0.175"/>
      <mass value="279.2"/>
      <inertia ixx="9.522" ixy="0" ixz="0" iyy="1966.28" iyz="0" izz="1966.28"/>
    </inertial>
    <visual>
      <origin rpy="0 1.5708 0" xyz="-0.25082 0 -0.175"/>
      <geometry>
        <mesh filename="package://simulation/models/canadarm/meshes/link_joint_v2_1.dae" scale="1.0 1.0 1.0"/>
      </geometry>
    </visual>
    <collision>
      <origin rpy="0 1.5708 0" xyz="-0.25082 0 -0.175"/>
      <geometry>
        <mesh filename="package://simulation/models/canadarm/meshes/link_joint_v2_1.stl" scale="1.0 1.0 1.0"/>
      </geometry>
    </collision>
    <visual>
      <origin rpy="1.57 -3.14 1.57" xyz="-7.36082 0 -0.175"/>
      <geometry>
        <mesh filename="package://simulation/models/canadarm/meshes/long_link_2_v3_0.dae" scale="1.0 1.0 1.0"/>
      </geometry>
    </visual>
    <collision>
      <origin rpy="1.57 -3.14 1.57" xyz="-7.36082 0 -0.175"/>
      <geometry>
        <mesh filename="package://simulation/models/canadarm/meshes/long_link_2_v3_0.stl" scale="1.0 1.0 1.0"/>
      </geometry>
    </collision>
    <visual>
      <origin rpy="0 -1.57 0" xyz="-7.36082 0 -0.175"/>
      <geometry>
        <mesh filename="package://simulation/models/canadarm/meshes/joint_v3_0.dae" scale="1.0 1.0 1.0"/>
      </geometry>
    </visual>
    <collision>
      <origin rpy="0 -1.57 0" xyz="-7.36082 0 -0.175"/>
      <geometry>
        <mesh filename="package://simulation/models/canadarm/meshes/joint_v3_0.stl" scale="1.0 1.0 1.0"/>
      </geometry>
    </collision>
  </link>
  <!-- Joint 5: Wrist Pitch Joint -->
  <joint name="Wrist_Pitch" type="revolute">
    <parent link="B4"/>
    <child link="B5"/>
    <origin rpy="0 0 0" xyz="-7.61164 0 -0.35"/>
    <axis xyz="0 0 -1"/>
    <limit effort="2332" lower="-4.71239" upper="4.71239" velocity="0.0698132"/>
  </joint>
  <!-- Link 6 -->
  <link name="B5">
    <inertial>
      <origin rpy="1.5708 0 0" xyz="0 0 0.0"/>
      <mass value="105.98"/>
      <inertia ixx="8.305" ixy="0" ixz="0" iyy="3.061" iyz="0" izz="8.0386"/>
    </inertial>
    <visual>
      <origin rpy="0 -3.14 0" xyz="0 0 0"/>
      <geometry>
        <mesh filename="package://simulation/models/canadarm/meshes/joint_v3_0.dae" scale="1.0 1.0 1.0"/>
      </geometry>
    </visual>
    <collision>
      <origin rpy="0 -3.14 0" xyz="0 0 0"/>
      <geometry>
        <mesh filename="package://simulation/models/canadarm/meshes/joint_v3_0.stl" scale="1.0 1.0 1.0"/>
      </geometry>
    </collision>
  </link>
  <!-- Joint 6: Wrist Yaw Joint -->
  <joint name="Wrist_Yaw" type="revolute">
    <parent link="B5"/>
    <child link="B6"/>
    <origin rpy="0 0 0" xyz="-0.175 0 -0.25082"/>
    <axis xyz="1 0 0"/>
    <limit effort="2332" lower="-4.71239" upper="4.71239" velocity="0.0698132"/>
  </joint>
  <!-- Link 7 -->
  <link name="B6">
    <inertial>
      <origin rpy="0 -1.5708 0" xyz="0 0 0"/>
      <mass value="105.98"/>
      <inertia ixx="12.13" ixy="0" ixz="0" iyy="12.13" iyz="0" izz="3.061"/>
    </inertial>
    <visual>
      <origin rpy="0 -1.5708 0" xyz="0 0 0"/>
      <geometry>
        <mesh filename="package://simulation/models/canadarm/meshes/joint_v3_0.dae" scale="1.0 1.0 1.0"/>
      </geometry>
    </visual>
    <collision>
      <origin rpy="0 -1.5708 0" xyz="0 0 0"/>
      <geometry>
        <mesh filename="package://simulation/models/canadarm/meshes/joint_v3_0.stl" scale="1.0 1.0 1.0"/>
      </geometry>
    </collision>
  </link>
  <!-- Joint 7: Wrist Roll Joint -->
  <joint name="Wrist_Roll" type="revolute">
    <parent link="B6"/>
    <child link="EE_SSRMS"/>
    <origin rpy="0 0 0" xyz="-0.25082 0 -0.175"/>
    <axis xyz="0 0 1"/>
    <limit effort="2332" lower="-4.71239" upper="4.71239" velocity="0.0698132"/>
  </joint>
  <!-- Link 8 -->
  <link name="EE_SSRMS">
    <inertial>
      <origin rpy="0 1.5708 0" xyz="0 0 -0.5"/>
      <mass value="243.66"/>
      <inertia ixx="9.336" ixy="0" ixz="0" iyy="44.41" iyz="0" izz="44.41"/>
    </inertial>
    <visual>
      <origin rpy="0 -3.1415 0" xyz="0 0 0"/>
      <geometry>
        <mesh filename="package://simulation/models/canadarm/meshes/ee.dae" scale="1.0 1.0 1.0"/>
      </geometry>
    </visual>
    <collision>
      <origin rpy="0 -3.1415 0" xyz="0 0 0"/>
      <geometry>
        <mesh filename="package://simulation/models/canadarm/meshes/ee.stl" scale="1.0 1.0 1.0"/>
      </geometry>
    </collision>
  </link>
  <!-- Dummy Tip Link -->
  <link name="EE_SSRMS_tip">
    <inertial>
      <origin rpy="0 0 0" xyz="0 0 0"/>
      <mass value="0.001"/>
      <inertia ixx="1e-9" ixy="0" ixz="0" iyy="1e-9" iyz="0" izz="1e-9"/>
    </inertial>
    <!-- <visual>
      <origin rpy="0 0 0" xyz="0 0 0"/>
      <geometry>
        <box size="0.5 0.05 0.1"/>
      </geometry>
      <material name="green">
        <color rgba="0.5 0.5 0.5 1.0"/>
      </material>
    </visual> -->
  </link>
  <!-- Fixed joint attaching tip to EE -->
  <joint name="EE_SSRMS_to_tip" type="fixed">
    <parent link="EE_SSRMS"/>
    <child link="EE_SSRMS_tip"/>
    <origin rpy="0 3.141592653589793 0" xyz="0 0 -1.4"/>
  </joint>
  <joint name="head_camera_joint" type="fixed">
    <parent link="EE_SSRMS_tip"/>
    <child link="camera_link"/>
    <origin rpy="0 -1.5707963267948966 0" xyz="0.4 -0.004 -0.15"/>
  </joint>
  <link name="camera_link">
    <inertial>
      <origin rpy="0 0 0" xyz="0 0 0"/>
      <mass value="0.001"/>
      <inertia ixx="9.1875e-09" ixy="0.0" ixz="0.0" iyy="9.1875e-09" iyz="0.0" izz="1.378125e-08"/>
    </inertial>
    <visual>
      <origin rpy="0.0 0 0" xyz="0 0 0"/>
      <geometry>
        <box size="0.0005 0.0005 0.0005"/>
      </geometry>
      <material name="green"/>
    </visual>
  </link>
  <joint name="base_camera_joint" type="fixed">
    <parent link="B1"/>
    <child link="base_camera_link"/>
    <origin rpy="0 1.5707963267948966 0" xyz="-0.292 -0.003 -1.15"/>
  </joint>
  <link name="base_camera_link">
    <inertial>
      <origin rpy="0 0 0" xyz="0 0 0"/>
      <mass value="0.001"/>
      <inertia ixx="9.1875e-09" ixy="0.0" ixz="0.0" iyy="9.1875e-09" iyz="0.0" izz="1.378125e-08"/>
    </inertial>
    <visual>
      <origin rpy="0.0 0 0" xyz="0 0 0"/>
      <geometry>
        <box size="0.0005 0.0005 0.0005"/>
      </geometry>
      <material name="green"/>
    </visual>
  </link>
</robot>
